Lmod has detected the following error: The following module(s) are unknown:
"cuda/12.1"

Please check the spelling or version number. Also try "module spider ..."
It is also possible your cache file is out-of-date; it may help to try:
  $ module --ignore_cache load "cuda/12.1"

Also make sure that all modulefiles written in TCL start with the string
#%Module



cuda available with GPU: Tesla V100-SXM2-16GB
[I] Loading dataset OGBG-MOLPCBA...
Traceback (most recent call last):
  File "/cvmfs/soft.computecanada.ca/easybuild/software/2023/x86-64-v4/Compiler/gcccore/python/3.10.13/lib/python3.10/urllib/request.py", line 1348, in do_open
    h.request(req.get_method(), req.selector, req.data, headers,
  File "/cvmfs/soft.computecanada.ca/easybuild/software/2023/x86-64-v4/Compiler/gcccore/python/3.10.13/lib/python3.10/http/client.py", line 1283, in request
    self._send_request(method, url, body, headers, encode_chunked)
  File "/cvmfs/soft.computecanada.ca/easybuild/software/2023/x86-64-v4/Compiler/gcccore/python/3.10.13/lib/python3.10/http/client.py", line 1329, in _send_request
    self.endheaders(body, encode_chunked=encode_chunked)
  File "/cvmfs/soft.computecanada.ca/easybuild/software/2023/x86-64-v4/Compiler/gcccore/python/3.10.13/lib/python3.10/http/client.py", line 1278, in endheaders
    self._send_output(message_body, encode_chunked=encode_chunked)
  File "/cvmfs/soft.computecanada.ca/easybuild/software/2023/x86-64-v4/Compiler/gcccore/python/3.10.13/lib/python3.10/http/client.py", line 1038, in _send_output
    self.send(msg)
  File "/cvmfs/soft.computecanada.ca/easybuild/software/2023/x86-64-v4/Compiler/gcccore/python/3.10.13/lib/python3.10/http/client.py", line 976, in send
    self.connect()
  File "/cvmfs/soft.computecanada.ca/easybuild/software/2023/x86-64-v4/Compiler/gcccore/python/3.10.13/lib/python3.10/http/client.py", line 942, in connect
    self.sock = self._create_connection(
  File "/cvmfs/soft.computecanada.ca/easybuild/software/2023/x86-64-v4/Compiler/gcccore/python/3.10.13/lib/python3.10/socket.py", line 845, in create_connection
    raise err
  File "/cvmfs/soft.computecanada.ca/easybuild/software/2023/x86-64-v4/Compiler/gcccore/python/3.10.13/lib/python3.10/socket.py", line 833, in create_connection
    sock.connect(sa)
ConnectionRefusedError: [Errno 111] Connection refused

During handling of the above exception, another exception occurred:

Traceback (most recent call last):
  File "/home/mikemont/final_project/gnn-lspe/main_OGBMOL_graph_classification.py", line 510, in <module>
    main()
  File "/home/mikemont/final_project/gnn-lspe/main_OGBMOL_graph_classification.py", line 392, in main
    dataset = LoadData(DATASET_NAME)
  File "/home/mikemont/final_project/gnn-lspe/data/data.py", line 21, in LoadData
    return OGBMOLDataset(DATASET_NAME)
  File "/home/mikemont/final_project/gnn-lspe/data/ogb_mol.py", line 179, in __init__
    self.dataset = DglGraphPropPredDataset(name=self.name, root='dataset')
  File "/home/mikemont/final_project/gnn-lspe/gnn_lspe_env/lib/python3.10/site-packages/ogb/graphproppred/dataset_dgl.py", line 68, in __init__
    self.pre_process()
  File "/home/mikemont/final_project/gnn-lspe/gnn_lspe_env/lib/python3.10/site-packages/ogb/graphproppred/dataset_dgl.py", line 100, in pre_process
    if decide_download(url):
  File "/home/mikemont/final_project/gnn-lspe/gnn_lspe_env/lib/python3.10/site-packages/ogb/utils/url.py", line 12, in decide_download
    d = ur.urlopen(url)
  File "/cvmfs/soft.computecanada.ca/easybuild/software/2023/x86-64-v4/Compiler/gcccore/python/3.10.13/lib/python3.10/urllib/request.py", line 216, in urlopen
    return opener.open(url, data, timeout)
  File "/cvmfs/soft.computecanada.ca/easybuild/software/2023/x86-64-v4/Compiler/gcccore/python/3.10.13/lib/python3.10/urllib/request.py", line 519, in open
    response = self._open(req, data)
  File "/cvmfs/soft.computecanada.ca/easybuild/software/2023/x86-64-v4/Compiler/gcccore/python/3.10.13/lib/python3.10/urllib/request.py", line 536, in _open
    result = self._call_chain(self.handle_open, protocol, protocol +
  File "/cvmfs/soft.computecanada.ca/easybuild/software/2023/x86-64-v4/Compiler/gcccore/python/3.10.13/lib/python3.10/urllib/request.py", line 496, in _call_chain
    result = func(*args)
  File "/cvmfs/soft.computecanada.ca/easybuild/software/2023/x86-64-v4/Compiler/gcccore/python/3.10.13/lib/python3.10/urllib/request.py", line 1377, in http_open
    return self.do_open(http.client.HTTPConnection, req)
  File "/cvmfs/soft.computecanada.ca/easybuild/software/2023/x86-64-v4/Compiler/gcccore/python/3.10.13/lib/python3.10/urllib/request.py", line 1351, in do_open
    raise URLError(err)
urllib.error.URLError: <urlopen error [Errno 111] Connection refused>
